{
  "title": "test_report_failure_message panic: assertion failed: result.is_err()",
  "description_summary": "The `debug_report::tests::test_report_failure_message` test is panicking with the assertion `result.is_err()`. The expected behavior is not clearly defined, but the test is failing due to this assertion. The full panic message and backtrace were not provided despite requests.",
  "steps_to_reproduce": [
    "Run the `debug_report::tests::test_report_failure_message` test."
  ],
  "expected_result": "The test should pass, indicating that `result.is_err()` is true.",
  "actual_result": "The test panics with the message \"assertion failed: result.is_err()\".  The test output shows: `test result: FAILED(B. 80 passed; 1 failed; 2 ignored; 0 measured; 0 filtered out; finished in 1.04s` and `error: test failed, to rerun pass --lib`",
  "environment": {
    "operating_system": "Unknown",
    "browser": "N/A",
    "software_version": "Unknown",
    "device": "N/A",
    "other_details": "Rust compiler version: Unknown. Library/application version: Unknown."
  },
  "severity": "High",
  "priority": "High",
  "reporter": "Anonymous",
  "attachments": null,
  "rate_of_reproduction": "Always"
}